{
	"id": "CVE-2021-21239",
	"description": "PySAML2 is a pure python implementation of SAML Version 2 Standard. PySAML2 before 6.5.0 has an improper verification of cryptographic signature vulnerability. Users of pysaml2 that use the default CryptoBackendXmlSec1 backend and need to verify signed SAML documents are impacted. PySAML2 does not ensure that a signed SAML document is correctly signed. The default CryptoBackendXmlSec1 backend is using the xmlsec1 binary to verify the signature of signed SAML documents, but by default xmlsec1 accepts any type of key found within the given document. xmlsec1 needs to be configured explicitly to only use only _x509 certificates_ for the verification process of the SAML document signature. This is fixed in PySAML2 6.5.0.\n\nAffected: IdentityPython pysaml2 < 6.5.0",
	"hardware": [],
	"software": [
		{
			"name": "python-pysaml2",
			"platform": "archlinux",
			"version": "< 6.5.1-1"
		},
		{
			"name": "python-pysaml2",
			"platform": "debian-12",
			"version": "< 6.5.1-1"
		},
		{
			"name": "python-pysaml2",
			"platform": "debian-11",
			"version": "< 6.5.1-1"
		},
		{
			"name": "python-pysaml2",
			"platform": "debian-10",
			"version": "*"
		},
		{
			"name": "python-pysaml2",
			"platform": "debian-9",
			"version": "< 3.0.0-5+deb9u2"
		},
		{
			"name": "python-pysaml2",
			"platform": "archlinux",
			"version": "< 6.5.1-1"
		},
		{
			"name": "python-pysaml2",
			"platform": "debian-12",
			"version": "< 6.5.1-1"
		},
		{
			"name": "python-pysaml2",
			"platform": "debian-11",
			"version": "< 6.5.1-1"
		},
		{
			"name": "python-pysaml2",
			"platform": "debian-10",
			"version": "*"
		},
		{
			"name": "python-pysaml2",
			"platform": "debian-9",
			"version": "< 3.0.0-5+deb9u2"
		},
		{
			"name": "python-pysaml2",
			"platform": "archlinux",
			"version": "< 6.5.1-1"
		},
		{
			"name": "python-pysaml2",
			"platform": "archlinux",
			"version": "< 6.5.1-1"
		},
		{
			"name": "python-pysaml2",
			"platform": "archlinux",
			"version": "< 6.5.1-1"
		},
		{
			"name": "python-pysaml2",
			"platform": "archlinux",
			"version": "< 6.5.1-1"
		},
		{
			"name": "python-pysaml2",
			"platform": "debian-12",
			"version": "< 6.5.1-1"
		},
		{
			"name": "python-pysaml2",
			"platform": "debian-11",
			"version": "< 6.5.1-1"
		},
		{
			"name": "python-pysaml2",
			"platform": "debian-10",
			"version": "*"
		},
		{
			"name": "python-pysaml2",
			"platform": "archlinux",
			"version": "< 6.5.1-1"
		},
		{
			"name": "python-pysaml2",
			"platform": "archlinux",
			"version": "< 6.5.1-1"
		},
		{
			"name": "python-pysaml2",
			"platform": "debian-12",
			"version": "< 6.5.1-1"
		},
		{
			"name": "python-pysaml2",
			"platform": "debian-11",
			"version": "< 6.5.1-1"
		},
		{
			"name": "python-pysaml2",
			"platform": "debian-10",
			"version": "*"
		}
	],
	"references": [
		"https://github.com/IdentityPython/pysaml2/security/advisories/GHSA-5p3x-r448-pc62",
		"https://github.com/IdentityPython/pysaml2/commit/751dbf50a51131b13d55989395f9b115045f9737",
		"https://www.aleksey.com/pipermail/xmlsec/2013/009717.html",
		"https://nvd.nist.gov/vuln/detail/CVE-2021-21239",
		"https://pypi.org/project/pysaml2",
		"https://github.com/IdentityPython/pysaml2/releases/tag/v6.5.0",
		"https://github.com/IdentityPython/pysaml2/commit/46578df0695269a16f1c94171f1429873f90ed99",
		"https://lists.debian.org/debian-lts-announce/2021/02/msg00038.html"
	],
	"severity": "critical",
	"state": "invalid",
	"_is_edited": false
}