{
	"id": "CVE-2020-13596",
	"description": "A possible XSS has been found in Django before 3.0.7, via admin ForeignKeyRawIdWidget. Query parameters for the admin ForeignKeyRawIdWidget were not properly URL encoded, posing an XSS attack vector.",
	"hardware": [],
	"software": [
		{
			"name": "python-django",
			"platform": "archlinux",
			"version": "< 3.0.7-1"
		},
		{
			"name": "python-django",
			"platform": "debian-9",
			"version": "< 1:1.10.7-2+deb9u9"
		},
		{
			"name": "python-django",
			"platform": "debian-10",
			"version": "< 1:1.11.29-1~deb10u1"
		},
		{
			"name": "python-django",
			"platform": "debian-1.1",
			"version": "< 1:1.10.7-2+deb9u9"
		},
		{
			"name": "python-django",
			"platform": "debian-1.2",
			"version": "< 1:1.10.7-2+deb9u9"
		},
		{
			"name": "python-django",
			"platform": "debian-1.3",
			"version": "< 1:1.10.7-2+deb9u9"
		},
		{
			"name": "python-django",
			"platform": "debian-2",
			"version": "< 1:1.10.7-2+deb9u9"
		},
		{
			"name": "python-django",
			"platform": "debian-2.1",
			"version": "< 1:1.10.7-2+deb9u9"
		},
		{
			"name": "python-django",
			"platform": "debian-2.2",
			"version": "< 1:1.10.7-2+deb9u9"
		},
		{
			"name": "python-django",
			"platform": "debian-3",
			"version": "< 1:1.10.7-2+deb9u9"
		},
		{
			"name": "python-django",
			"platform": "debian-3.1",
			"version": "< 1:1.10.7-2+deb9u9"
		},
		{
			"name": "python-django",
			"platform": "debian-4",
			"version": "< 1:1.10.7-2+deb9u9"
		},
		{
			"name": "python-django",
			"platform": "debian-5",
			"version": "< 1:1.10.7-2+deb9u9"
		},
		{
			"name": "python-django",
			"platform": "debian-6",
			"version": "< 1:1.10.7-2+deb9u9"
		},
		{
			"name": "python-django",
			"platform": "debian-7",
			"version": "< 1:1.10.7-2+deb9u9"
		},
		{
			"name": "python-django",
			"platform": "debian-8",
			"version": "< 1:1.10.7-2+deb9u9"
		},
		{
			"name": "python-django",
			"platform": "debian-1.1",
			"version": "< 1:1.11.29-1~deb10u1"
		},
		{
			"name": "python-django",
			"platform": "debian-1.2",
			"version": "< 1:1.11.29-1~deb10u1"
		},
		{
			"name": "python-django",
			"platform": "debian-1.3",
			"version": "< 1:1.11.29-1~deb10u1"
		},
		{
			"name": "python-django",
			"platform": "debian-2",
			"version": "< 1:1.11.29-1~deb10u1"
		},
		{
			"name": "python-django",
			"platform": "debian-2.1",
			"version": "< 1:1.11.29-1~deb10u1"
		},
		{
			"name": "python-django",
			"platform": "debian-2.2",
			"version": "< 1:1.11.29-1~deb10u1"
		},
		{
			"name": "python-django",
			"platform": "debian-3",
			"version": "< 1:1.11.29-1~deb10u1"
		},
		{
			"name": "python-django",
			"platform": "debian-3.1",
			"version": "< 1:1.11.29-1~deb10u1"
		},
		{
			"name": "python-django",
			"platform": "debian-4",
			"version": "< 1:1.11.29-1~deb10u1"
		},
		{
			"name": "python-django",
			"platform": "debian-5",
			"version": "< 1:1.11.29-1~deb10u1"
		},
		{
			"name": "python-django",
			"platform": "debian-6",
			"version": "< 1:1.11.29-1~deb10u1"
		},
		{
			"name": "python-django",
			"platform": "debian-7",
			"version": "< 1:1.11.29-1~deb10u1"
		},
		{
			"name": "python-django",
			"platform": "debian-8",
			"version": "< 1:1.11.29-1~deb10u1"
		},
		{
			"name": "python-django",
			"platform": "debian-9",
			"version": "< 1:1.11.29-1~deb10u1"
		},
		{
			"name": "python-django",
			"platform": "debian-12",
			"version": "< 2:2.2.13-1"
		},
		{
			"name": "python-django",
			"platform": "debian-11",
			"version": "< 2:2.2.13-1"
		}
	],
	"references": [
		"https://www.djangoproject.com/weblog/2020/jun/03/security-releases/",
		"https://github.com/django/django/commit/1f2dd37f6fcefdd10ed44cb233b2e62b520afb38",
		"https://security-tracker.debian.org/tracker/DSA-4705-1"
	],
	"severity": "medium",
	"state": "invalid",
	"is_edited": false
}