{
	"identifier": "CVE-2020-35917",
	"description": "An issue was discovered in the pyo3 crate before 0.12.4 for Rust. There is a reference-counting error and use-after-free in From\u003cPy\u003cT\u003e\u003e.",
	"type": "local",
	"severity": "low",
	"state": "published",
	"datetime": "2020-12-31T08:15:15Z",
	"is_edited": false,
	"hardware": [],
	"software": [],
	"products": [
		{
			"name": "pyo3",
			"version": "\u003c 0.12.4",
			"architecture": "any",
			"vendor": "pyo3-project",
			"type": "software",
			"is_edited": false,
			"aliases": []
		}
	],
	"references": [
		"https://rustsec.org/advisories/RUSTSEC-2020-0074.html"
	],
	"weaknesses": [
		"CWE-416"
	]
}